<sdf version='1.6'>
  <world name='default'>
    <light name='sun' type='directional'>
      <cast_shadows>1</cast_shadows>
      <pose frame=''>0 0 10 0 -0 0</pose>
      <diffuse>0.8 0.8 0.8 1</diffuse>
      <specular>0.2 0.2 0.2 1</specular>
      <attenuation>
        <range>1000</range>
        <constant>0.9</constant>
        <linear>0.01</linear>
        <quadratic>0.001</quadratic>
      </attenuation>
      <direction>-0.5 0.1 -0.9</direction>
    </light>
    <model name='ground_plane'>
      <static>1</static>
      <link name='link'>
        <collision name='collision'>
          <geometry>
            <plane>
              <normal>0 0 1</normal>
              <size>100 100</size>
            </plane>
          </geometry>
          <surface>
            <contact>
              <collide_bitmask>65535</collide_bitmask>
              <ode/>
            </contact>
            <friction>
              <ode>
                <mu>100</mu>
                <mu2>50</mu2>
              </ode>
              <torsional>
                <ode/>
              </torsional>
            </friction>
            <bounce/>
          </surface>
          <max_contacts>10</max_contacts>
        </collision>
        <visual name='visual'>
          <cast_shadows>0</cast_shadows>
          <geometry>
            <plane>
              <normal>0 0 1</normal>
              <size>100 100</size>
            </plane>
          </geometry>
          <material>
            <script>
              <uri>file://media/materials/scripts/gazebo.material</uri>
              <name>Gazebo/Grey</name>
            </script>
          </material>
        </visual>
        <self_collide>0</self_collide>
        <enable_wind>0</enable_wind>
        <kinematic>0</kinematic>
      </link>
    </model>
    <gravity>0 0 -9.8</gravity>
    <magnetic_field>6e-06 2.3e-05 -4.2e-05</magnetic_field>
    <atmosphere type='adiabatic'/>
    <physics name='default_physics' default='0' type='ode'>
      <max_step_size>0.001</max_step_size>
      <real_time_factor>1</real_time_factor>
      <real_time_update_rate>1000</real_time_update_rate>
    </physics>
    <scene>
      <ambient>0.4 0.4 0.4 1</ambient>
      <background>0.7 0.7 0.7 1</background>
      <shadows>1</shadows>
    </scene>
    <audio>
      <device>default</device>
    </audio>
    <wind/>
    <spherical_coordinates>
      <surface_model>EARTH_WGS84</surface_model>
      <latitude_deg>0</latitude_deg>
      <longitude_deg>0</longitude_deg>
      <elevation>0</elevation>
      <heading_deg>0</heading_deg>
    </spherical_coordinates>
    <model name='nexus_4wd_mecanum'>
      <link name='base_footprint'>
        <pose frame=''>0 0 0 0 -0 0</pose>
        <inertial>
          <pose frame=''>-0.010238 -0 0.051856 0 -0 0</pose>
          <mass>3.064</mass>
          <inertia>
            <ixx>0.0220853</ixx>
            <ixy>8.88007e-21</ixy>
            <ixz>-9.70143e-05</ixz>
            <iyy>0.0623492</iyy>
            <iyz>-3.80743e-17</iyz>
            <izz>0.0824412</izz>
          </inertia>
        </inertial>
        <collision name='base_footprint_fixed_joint_lump__base_link_collision'>
          <pose frame=''>0 0 0.05 0 -0 0</pose>
          <geometry>
            <mesh>
              <scale>0.001 0.001 0.001</scale>
              <uri>/home/jin/Desktop/ws/src/nexus_4wd_mecanum_simulator-master/nexus_4wd_mecanum_description/meshes/nexus_base_link_collision.STL</uri>
            </mesh>
          </geometry>
          <surface>
            <contact>
              <ode/>
            </contact>
            <friction>
              <ode/>
              <torsional>
                <ode/>
              </torsional>
            </friction>
            <bounce/>
          </surface>
          <max_contacts>10</max_contacts>
        </collision>
        <collision name='base_footprint_fixed_joint_lump__lower_left_wheel_shaft_collision_1'>
          <pose frame=''>-0.15 0.108 0.05 0 -0 0</pose>
          <geometry>
            <mesh>
              <scale>0.001 0.001 0.001</scale>
              <uri>/home/jin/Desktop/ws/src/nexus_4wd_mecanum_simulator-master/nexus_4wd_mecanum_description/meshes/wheel_shaft.STL</uri>
            </mesh>
          </geometry>
          <surface>
            <contact>
              <ode/>
            </contact>
            <friction>
              <ode/>
              <torsional>
                <ode/>
              </torsional>
            </friction>
            <bounce/>
          </surface>
          <max_contacts>10</max_contacts>
        </collision>
        <collision name='base_footprint_fixed_joint_lump__lower_right_wheel_shaft_collision_2'>
          <pose frame=''>-0.15 -0.108 0.05 -3.14159 -0 0</pose>
          <geometry>
            <mesh>
              <scale>0.001 0.001 0.001</scale>
              <uri>/home/jin/Desktop/ws/src/nexus_4wd_mecanum_simulator-master/nexus_4wd_mecanum_description/meshes/wheel_shaft.STL</uri>
            </mesh>
          </geometry>
          <surface>
            <contact>
              <ode/>
            </contact>
            <friction>
              <ode/>
              <torsional>
                <ode/>
              </torsional>
            </friction>
            <bounce/>
          </surface>
          <max_contacts>10</max_contacts>
        </collision>
        <collision name='base_footprint_fixed_joint_lump__upper_left_wheel_shaft_collision_3'>
          <pose frame=''>0.15 0.108 0.05 0 -0 0</pose>
          <geometry>
            <mesh>
              <scale>0.001 0.001 0.001</scale>
              <uri>/home/jin/Desktop/ws/src/nexus_4wd_mecanum_simulator-master/nexus_4wd_mecanum_description/meshes/wheel_shaft.STL</uri>
            </mesh>
          </geometry>
          <surface>
            <contact>
              <ode/>
            </contact>
            <friction>
              <ode/>
              <torsional>
                <ode/>
              </torsional>
            </friction>
            <bounce/>
          </surface>
          <max_contacts>10</max_contacts>
        </collision>
        <collision name='base_footprint_fixed_joint_lump__upper_right_wheel_shaft_collision_4'>
          <pose frame=''>0.15 -0.108 0.05 -3.14159 -0 0</pose>
          <geometry>
            <mesh>
              <scale>0.001 0.001 0.001</scale>
              <uri>/home/jin/Desktop/ws/src/nexus_4wd_mecanum_simulator-master/nexus_4wd_mecanum_description/meshes/wheel_shaft.STL</uri>
            </mesh>
          </geometry>
          <surface>
            <contact>
              <ode/>
            </contact>
            <friction>
              <ode/>
              <torsional>
                <ode/>
              </torsional>
            </friction>
            <bounce/>
          </surface>
          <max_contacts>10</max_contacts>
        </collision>
        <visual name='base_footprint_fixed_joint_lump__base_link_visual'>
          <pose frame=''>0 0 0.05 0 -0 0</pose>
          <geometry>
            <mesh>
              <scale>0.001 0.001 0.001</scale>
              <uri>/home/jin/Desktop/ws/src/nexus_4wd_mecanum_simulator-master/nexus_4wd_mecanum_description/meshes/nexus_base_link.STL</uri>
            </mesh>
          </geometry>
          <material>
            <script>
              <name>Gazebo/Yellow</name>
              <uri>file://media/materials/scripts/gazebo.material</uri>
            </script>
          </material>
        </visual>
        <visual name='base_footprint_fixed_joint_lump__front_sensor_visual_1'>
          <pose frame=''>0.205 0 0.06 1.5708 -0 0</pose>
          <geometry>
            <mesh>
              <scale>0.001 0.001 0.001</scale>
              <uri>/home/jin/Desktop/ws/src/nexus_4wd_mecanum_simulator-master/nexus_4wd_mecanum_description/meshes/urm04.STL</uri>
            </mesh>
          </geometry>
          <material>
            <script>
              <name>Gazebo/Black</name>
              <uri>file://media/materials/scripts/gazebo.material</uri>
            </script>
          </material>
        </visual>
        <visual name='base_footprint_fixed_joint_lump__left_sensor_visual_2'>
          <pose frame=''>0 0.108 0.06 1.5708 -0 1.5708</pose>
          <geometry>
            <mesh>
              <scale>0.001 0.001 0.001</scale>
              <uri>/home/jin/Desktop/ws/src/nexus_4wd_mecanum_simulator-master/nexus_4wd_mecanum_description/meshes/urm04.STL</uri>
            </mesh>
          </geometry>
          <material>
            <script>
              <name>Gazebo/Black</name>
              <uri>file://media/materials/scripts/gazebo.material</uri>
            </script>
          </material>
        </visual>
        <visual name='base_footprint_fixed_joint_lump__lower_left_wheel_shaft_visual_3'>
          <pose frame=''>-0.15 0.108 0.05 0 -0 0</pose>
          <geometry>
            <mesh>
              <scale>0.001 0.001 0.001</scale>
              <uri>/home/jin/Desktop/ws/src/nexus_4wd_mecanum_simulator-master/nexus_4wd_mecanum_description/meshes/wheel_shaft.STL</uri>
            </mesh>
          </geometry>
          <material>
            <script>
              <name>Gazebo/Black</name>
              <uri>file://media/materials/scripts/gazebo.material</uri>
            </script>
          </material>
        </visual>
        <visual name='base_footprint_fixed_joint_lump__lower_right_wheel_shaft_visual_4'>
          <pose frame=''>-0.15 -0.108 0.05 -3.14159 -0 0</pose>
          <geometry>
            <mesh>
              <scale>0.001 0.001 0.001</scale>
              <uri>/home/jin/Desktop/ws/src/nexus_4wd_mecanum_simulator-master/nexus_4wd_mecanum_description/meshes/wheel_shaft.STL</uri>
            </mesh>
          </geometry>
          <material>
            <script>
              <name>Gazebo/Black</name>
              <uri>file://media/materials/scripts/gazebo.material</uri>
            </script>
          </material>
        </visual>
        <visual name='base_footprint_fixed_joint_lump__rear_sensor_visual_5'>
          <pose frame=''>-0.201 0 0.06 1.5708 -0 -3.14159</pose>
          <geometry>
            <mesh>
              <scale>0.001 0.001 0.001</scale>
              <uri>/home/jin/Desktop/ws/src/nexus_4wd_mecanum_simulator-master/nexus_4wd_mecanum_description/meshes/urm04.STL</uri>
            </mesh>
          </geometry>
          <material>
            <script>
              <name>Gazebo/Black</name>
              <uri>file://media/materials/scripts/gazebo.material</uri>
            </script>
          </material>
        </visual>
        <visual name='base_footprint_fixed_joint_lump__right_sensor_visual_6'>
          <pose frame=''>0 -0.108 0.06 1.5708 0 -1.5708</pose>
          <geometry>
            <mesh>
              <scale>0.001 0.001 0.001</scale>
              <uri>/home/jin/Desktop/ws/src/nexus_4wd_mecanum_simulator-master/nexus_4wd_mecanum_description/meshes/urm04.STL</uri>
            </mesh>
          </geometry>
          <material>
            <script>
              <name>Gazebo/Black</name>
              <uri>file://media/materials/scripts/gazebo.material</uri>
            </script>
          </material>
        </visual>
        <visual name='base_footprint_fixed_joint_lump__upper_left_wheel_shaft_visual_7'>
          <pose frame=''>0.15 0.108 0.05 0 -0 0</pose>
          <geometry>
            <mesh>
              <scale>0.001 0.001 0.001</scale>
              <uri>/home/jin/Desktop/ws/src/nexus_4wd_mecanum_simulator-master/nexus_4wd_mecanum_description/meshes/wheel_shaft.STL</uri>
            </mesh>
          </geometry>
          <material>
            <script>
              <name>Gazebo/Black</name>
              <uri>file://media/materials/scripts/gazebo.material</uri>
            </script>
          </material>
        </visual>
        <visual name='base_footprint_fixed_joint_lump__upper_right_wheel_shaft_visual_8'>
          <pose frame=''>0.15 -0.108 0.05 -3.14159 -0 0</pose>
          <geometry>
            <mesh>
              <scale>0.001 0.001 0.001</scale>
              <uri>/home/jin/Desktop/ws/src/nexus_4wd_mecanum_simulator-master/nexus_4wd_mecanum_description/meshes/wheel_shaft.STL</uri>
            </mesh>
          </geometry>
          <material>
            <script>
              <name>Gazebo/Black</name>
              <uri>file://media/materials/scripts/gazebo.material</uri>
            </script>
          </material>
        </visual>
        <velocity_decay/>
        <velocity_decay/>
        <velocity_decay/>
        <velocity_decay/>
        <sensor name='front_sensor' type='ray'>
          <always_on>1</always_on>
          <update_rate>10</update_rate>
          <visualize>0</visualize>
          <ray>
            <scan>
              <horizontal>
                <samples>2</samples>
                <resolution>1</resolution>
                <min_angle>-0.52</min_angle>
                <max_angle>0.52</max_angle>
              </horizontal>
              <vertical>
                <samples>2</samples>
                <resolution>1</resolution>
                <min_angle>-0.02</min_angle>
                <max_angle>0.02</max_angle>
              </vertical>
            </scan>
            <range>
              <min>0.04</min>
              <max>2.5</max>
              <resolution>0.01</resolution>
            </range>
          </ray>
          <plugin name='gazebo_ros_front_sensor' filename='libhector_gazebo_ros_sonar.so'>
            <gaussianNoise>0.005</gaussianNoise>
            <topicName>front_sensor</topicName>
            <frameId>front_sensor</frameId>
            <robotNamespace>/</robotNamespace>
          </plugin>
          <pose frame=''>0.205 0 0.06 0 -0 0</pose>
        </sensor>
        <velocity_decay/>
        <velocity_decay/>
        <sensor name='left_sensor' type='ray'>
          <always_on>1</always_on>
          <update_rate>10</update_rate>
          <visualize>0</visualize>
          <ray>
            <scan>
              <horizontal>
                <samples>2</samples>
                <resolution>1</resolution>
                <min_angle>-0.52</min_angle>
                <max_angle>0.52</max_angle>
              </horizontal>
              <vertical>
                <samples>2</samples>
                <resolution>1</resolution>
                <min_angle>-0.02</min_angle>
                <max_angle>0.02</max_angle>
              </vertical>
            </scan>
            <range>
              <min>0.04</min>
              <max>2.5</max>
              <resolution>0.01</resolution>
            </range>
          </ray>
          <plugin name='gazebo_ros_left_sensor' filename='libhector_gazebo_ros_sonar.so'>
            <gaussianNoise>0.005</gaussianNoise>
            <topicName>left_sensor</topicName>
            <frameId>left_sensor</frameId>
            <robotNamespace>/</robotNamespace>
          </plugin>
          <pose frame=''>0 0.108 0.06 0 -0 1.5708</pose>
        </sensor>
        <velocity_decay/>
        <velocity_decay/>
        <velocity_decay/>
        <velocity_decay/>
        <sensor name='rear_sensor' type='ray'>
          <always_on>1</always_on>
          <update_rate>10</update_rate>
          <visualize>0</visualize>
          <ray>
            <scan>
              <horizontal>
                <samples>2</samples>
                <resolution>1</resolution>
                <min_angle>-0.52</min_angle>
                <max_angle>0.52</max_angle>
              </horizontal>
              <vertical>
                <samples>2</samples>
                <resolution>1</resolution>
                <min_angle>-0.02</min_angle>
                <max_angle>0.02</max_angle>
              </vertical>
            </scan>
            <range>
              <min>0.04</min>
              <max>2.5</max>
              <resolution>0.01</resolution>
            </range>
          </ray>
          <plugin name='gazebo_ros_rear_sensor' filename='libhector_gazebo_ros_sonar.so'>
            <gaussianNoise>0.005</gaussianNoise>
            <topicName>rear_sensor</topicName>
            <frameId>rear_sensor</frameId>
            <robotNamespace>/</robotNamespace>
          </plugin>
          <pose frame=''>-0.201 0 0.06 0 -0 -3.14159</pose>
        </sensor>
        <velocity_decay/>
        <velocity_decay/>
        <sensor name='right_sensor' type='ray'>
          <always_on>1</always_on>
          <update_rate>10</update_rate>
          <visualize>0</visualize>
          <ray>
            <scan>
              <horizontal>
                <samples>2</samples>
                <resolution>1</resolution>
                <min_angle>-0.52</min_angle>
                <max_angle>0.52</max_angle>
              </horizontal>
              <vertical>
                <samples>2</samples>
                <resolution>1</resolution>
                <min_angle>-0.02</min_angle>
                <max_angle>0.02</max_angle>
              </vertical>
            </scan>
            <range>
              <min>0.04</min>
              <max>2.5</max>
              <resolution>0.01</resolution>
            </range>
          </ray>
          <plugin name='gazebo_ros_right_sensor' filename='libhector_gazebo_ros_sonar.so'>
            <gaussianNoise>0.005</gaussianNoise>
            <topicName>right_sensor</topicName>
            <frameId>right_sensor</frameId>
            <robotNamespace>/</robotNamespace>
          </plugin>
          <pose frame=''>0 -0.108 0.06 0 0 -1.5708</pose>
        </sensor>
        <gravity>1</gravity>
        <velocity_decay/>
        <gravity>1</gravity>
        <velocity_decay/>
        <self_collide>0</self_collide>
        <enable_wind>0</enable_wind>
        <kinematic>0</kinematic>
      </link>
      <link name='lower_left_wheel'>
        <pose frame=''>-0.15 0.15 0.05 0 -0 0</pose>
        <inertial>
          <pose frame=''>0 0 0 0 -0 0</pose>
          <mass>0.3844</mass>
          <inertia>
            <ixx>0.000324824</ixx>
            <ixy>0</ixy>
            <ixz>0</ixz>
            <iyy>0.00048</iyy>
            <iyz>0</iyz>
            <izz>0.000324824</izz>
          </inertia>
        </inertial>
        <collision name='lower_left_wheel_collision'>
          <pose frame=''>0 0 0 1.5708 -0 0</pose>
          <geometry>
            <cylinder>
              <length>0.0505</length>
              <radius>0.05</radius>
            </cylinder>
          </geometry>
          <surface>
            <contact>
              <ode/>
            </contact>
            <friction>
              <ode>
                <mu>0</mu>
                <mu2>0</mu2>
              </ode>
              <torsional>
                <ode/>
              </torsional>
            </friction>
            <bounce/>
          </surface>
          <max_contacts>10</max_contacts>
        </collision>
        <visual name='lower_left_wheel_visual'>
          <pose frame=''>0 0 0 0 -0 0</pose>
          <geometry>
            <mesh>
              <scale>0.001 0.001 0.001</scale>
              <uri>/home/jin/Desktop/ws/src/nexus_4wd_mecanum_simulator-master/nexus_4wd_mecanum_description/meshes/mecanum_wheel_right.STL</uri>
            </mesh>
          </geometry>
          <material>
            <script>
              <name>Gazebo/Grey</name>
              <uri>file://media/materials/scripts/gazebo.material</uri>
            </script>
          </material>
        </visual>
        <gravity>1</gravity>
        <velocity_decay/>
        <self_collide>0</self_collide>
        <enable_wind>0</enable_wind>
        <kinematic>0</kinematic>
      </link>
      <joint name='lower_left_wheel_joint' type='revolute'>
        <child>lower_left_wheel</child>
        <parent>base_footprint</parent>
        <axis>
          <xyz>0 1 0</xyz>
          <limit>
            <lower>-1e+16</lower>
            <upper>1e+16</upper>
          </limit>
          <dynamics>
            <spring_reference>0</spring_reference>
            <spring_stiffness>0</spring_stiffness>
          </dynamics>
          <use_parent_model_frame>1</use_parent_model_frame>
        </axis>
      </joint>
      <link name='lower_right_wheel'>
        <pose frame=''>-0.15 -0.15 0.05 -3.14159 -0 0</pose>
        <inertial>
          <pose frame=''>0 0 0 0 -0 0</pose>
          <mass>0.3844</mass>
          <inertia>
            <ixx>0.000324824</ixx>
            <ixy>0</ixy>
            <ixz>0</ixz>
            <iyy>0.00048</iyy>
            <iyz>0</iyz>
            <izz>0.000324824</izz>
          </inertia>
        </inertial>
        <collision name='lower_right_wheel_collision'>
          <pose frame=''>0 0 0 1.5708 -0 0</pose>
          <geometry>
            <cylinder>
              <length>0.0505</length>
              <radius>0.05</radius>
            </cylinder>
          </geometry>
          <surface>
            <contact>
              <ode/>
            </contact>
            <friction>
              <ode>
                <mu>0</mu>
                <mu2>0</mu2>
              </ode>
              <torsional>
                <ode/>
              </torsional>
            </friction>
            <bounce/>
          </surface>
          <max_contacts>10</max_contacts>
        </collision>
        <visual name='lower_right_wheel_visual'>
          <pose frame=''>0 0 0 0 -0 0</pose>
          <geometry>
            <mesh>
              <scale>0.001 0.001 0.001</scale>
              <uri>/home/jin/Desktop/ws/src/nexus_4wd_mecanum_simulator-master/nexus_4wd_mecanum_description/meshes/mecanum_wheel_left.STL</uri>
            </mesh>
          </geometry>
          <material>
            <script>
              <name>Gazebo/Grey</name>
              <uri>file://media/materials/scripts/gazebo.material</uri>
            </script>
          </material>
        </visual>
        <gravity>1</gravity>
        <velocity_decay/>
        <self_collide>0</self_collide>
        <enable_wind>0</enable_wind>
        <kinematic>0</kinematic>
      </link>
      <joint name='lower_right_wheel_joint' type='revolute'>
        <child>lower_right_wheel</child>
        <parent>base_footprint</parent>
        <axis>
          <xyz>0 -1 -0</xyz>
          <limit>
            <lower>-1e+16</lower>
            <upper>1e+16</upper>
          </limit>
          <dynamics>
            <spring_reference>0</spring_reference>
            <spring_stiffness>0</spring_stiffness>
          </dynamics>
          <use_parent_model_frame>1</use_parent_model_frame>
        </axis>
      </joint>
      <link name='upper_left_wheel'>
        <pose frame=''>0.15 0.15 0.05 0 -0 0</pose>
        <inertial>
          <pose frame=''>0 0 0 0 -0 0</pose>
          <mass>0.3844</mass>
          <inertia>
            <ixx>0.000324824</ixx>
            <ixy>0</ixy>
            <ixz>0</ixz>
            <iyy>0.00048</iyy>
            <iyz>0</iyz>
            <izz>0.000324824</izz>
          </inertia>
        </inertial>
        <collision name='upper_left_wheel_collision'>
          <pose frame=''>0 0 0 1.5708 -0 0</pose>
          <geometry>
            <cylinder>
              <length>0.0505</length>
              <radius>0.05</radius>
            </cylinder>
          </geometry>
          <surface>
            <contact>
              <ode/>
            </contact>
            <friction>
              <ode>
                <mu>0</mu>
                <mu2>0</mu2>
              </ode>
              <torsional>
                <ode/>
              </torsional>
            </friction>
            <bounce/>
          </surface>
          <max_contacts>10</max_contacts>
        </collision>
        <visual name='upper_left_wheel_visual'>
          <pose frame=''>0 0 0 0 -0 0</pose>
          <geometry>
            <mesh>
              <scale>0.001 0.001 0.001</scale>
              <uri>/home/jin/Desktop/ws/src/nexus_4wd_mecanum_simulator-master/nexus_4wd_mecanum_description/meshes/mecanum_wheel_left.STL</uri>
            </mesh>
          </geometry>
          <material>
            <script>
              <name>Gazebo/Grey</name>
              <uri>file://media/materials/scripts/gazebo.material</uri>
            </script>
          </material>
        </visual>
        <gravity>1</gravity>
        <velocity_decay/>
        <self_collide>0</self_collide>
        <enable_wind>0</enable_wind>
        <kinematic>0</kinematic>
      </link>
      <joint name='upper_left_wheel_joint' type='revolute'>
        <child>upper_left_wheel</child>
        <parent>base_footprint</parent>
        <axis>
          <xyz>0 1 0</xyz>
          <limit>
            <lower>-1e+16</lower>
            <upper>1e+16</upper>
          </limit>
          <dynamics>
            <spring_reference>0</spring_reference>
            <spring_stiffness>0</spring_stiffness>
          </dynamics>
          <use_parent_model_frame>1</use_parent_model_frame>
        </axis>
      </joint>
      <link name='upper_right_wheel'>
        <pose frame=''>0.15 -0.15 0.05 -3.14159 -0 0</pose>
        <inertial>
          <pose frame=''>0 0 0 0 -0 0</pose>
          <mass>0.3844</mass>
          <inertia>
            <ixx>0.000324824</ixx>
            <ixy>0</ixy>
            <ixz>0</ixz>
            <iyy>0.00048</iyy>
            <iyz>0</iyz>
            <izz>0.000324824</izz>
          </inertia>
        </inertial>
        <collision name='upper_right_wheel_collision'>
          <pose frame=''>0 0 0 1.5708 -0 0</pose>
          <geometry>
            <cylinder>
              <length>0.0505</length>
              <radius>0.05</radius>
            </cylinder>
          </geometry>
          <surface>
            <contact>
              <ode/>
            </contact>
            <friction>
              <ode>
                <mu>0</mu>
                <mu2>0</mu2>
              </ode>
              <torsional>
                <ode/>
              </torsional>
            </friction>
            <bounce/>
          </surface>
          <max_contacts>10</max_contacts>
        </collision>
        <visual name='upper_right_wheel_visual'>
          <pose frame=''>0 0 0 0 -0 0</pose>
          <geometry>
            <mesh>
              <scale>0.001 0.001 0.001</scale>
              <uri>/home/jin/Desktop/ws/src/nexus_4wd_mecanum_simulator-master/nexus_4wd_mecanum_description/meshes/mecanum_wheel_right.STL</uri>
            </mesh>
          </geometry>
          <material>
            <script>
              <name>Gazebo/Grey</name>
              <uri>file://media/materials/scripts/gazebo.material</uri>
            </script>
          </material>
        </visual>
        <gravity>1</gravity>
        <velocity_decay/>
        <self_collide>0</self_collide>
        <enable_wind>0</enable_wind>
        <kinematic>0</kinematic>
      </link>
      <joint name='upper_right_wheel_joint' type='revolute'>
        <child>upper_right_wheel</child>
        <parent>base_footprint</parent>
        <axis>
          <xyz>0 -1 -0</xyz>
          <limit>
            <lower>-1e+16</lower>
            <upper>1e+16</upper>
          </limit>
          <dynamics>
            <spring_reference>0</spring_reference>
            <spring_stiffness>0</spring_stiffness>
          </dynamics>
          <use_parent_model_frame>1</use_parent_model_frame>
        </axis>
      </joint>
      <static>0</static>
      <plugin name='nexus_ros_force_based_move' filename='libnexus_ros_force_based_move.so'>
        <commandTopic>cmd_vel</commandTopic>
        <odometryTopic>odom</odometryTopic>
        <odometryFrame>odom</odometryFrame>
        <odometryRate>25.0</odometryRate>
        <robotBaseFrame>base_footprint</robotBaseFrame>
        <cmdVelTimeOut>0.25</cmdVelTimeOut>
        <publishOdometryTf>0</publishOdometryTf>
        <yaw_velocity_p_gain>1.0</yaw_velocity_p_gain>
        <x_velocity_p_gain>15.0</x_velocity_p_gain>
        <y_velocity_p_gain>15.0</y_velocity_p_gain>
        <max_x_velocity>0.6</max_x_velocity>
        <max_y_velocity>0.6</max_y_velocity>
        <max_yaw_velocity>0.5</max_yaw_velocity>
        <robotNamespace>/</robotNamespace>
      </plugin>
      <pose frame=''>0 0 0.5 0 -0 0</pose>
    </model>
    <model name='unit_cylinder'>
      <pose frame=''>3.01943 2.55736 0.5 0 -0 0</pose>
      <link name='link'>
        <inertial>
          <mass>1</mass>
          <inertia>
            <ixx>0.145833</ixx>
            <ixy>0</ixy>
            <ixz>0</ixz>
            <iyy>0.145833</iyy>
            <iyz>0</iyz>
            <izz>0.125</izz>
          </inertia>
        </inertial>
        <collision name='collision'>
          <geometry>
            <cylinder>
              <radius>0.5</radius>
              <length>1</length>
            </cylinder>
          </geometry>
          <max_contacts>10</max_contacts>
          <surface>
            <contact>
              <ode/>
            </contact>
            <bounce/>
            <friction>
              <torsional>
                <ode/>
              </torsional>
              <ode/>
            </friction>
          </surface>
        </collision>
        <visual name='visual'>
          <geometry>
            <cylinder>
              <radius>0.5</radius>
              <length>1</length>
            </cylinder>
          </geometry>
          <material>
            <script>
              <name>Gazebo/Grey</name>
              <uri>file://media/materials/scripts/gazebo.material</uri>
            </script>
          </material>
        </visual>
        <self_collide>0</self_collide>
        <enable_wind>0</enable_wind>
        <kinematic>0</kinematic>
      </link>
    </model>
    <model name='unit_cylinder_0'>
      <pose frame=''>7.42106 4.65241 0.5 0 -0 0</pose>
      <link name='link'>
        <inertial>
          <mass>1</mass>
          <inertia>
            <ixx>0.145833</ixx>
            <ixy>0</ixy>
            <ixz>0</ixz>
            <iyy>0.145833</iyy>
            <iyz>0</iyz>
            <izz>0.125</izz>
          </inertia>
        </inertial>
        <collision name='collision'>
          <geometry>
            <cylinder>
              <radius>0.5</radius>
              <length>1</length>
            </cylinder>
          </geometry>
          <max_contacts>10</max_contacts>
          <surface>
            <contact>
              <ode/>
            </contact>
            <bounce/>
            <friction>
              <torsional>
                <ode/>
              </torsional>
              <ode/>
            </friction>
          </surface>
        </collision>
        <visual name='visual'>
          <geometry>
            <cylinder>
              <radius>0.5</radius>
              <length>1</length>
            </cylinder>
          </geometry>
          <material>
            <script>
              <name>Gazebo/Grey</name>
              <uri>file://media/materials/scripts/gazebo.material</uri>
            </script>
          </material>
        </visual>
        <self_collide>0</self_collide>
        <enable_wind>0</enable_wind>
        <kinematic>0</kinematic>
      </link>
    </model>
    <state world_name='default'>
      <sim_time>152 70000000</sim_time>
      <real_time>154 3956118</real_time>
      <wall_time>1654684840 842861686</wall_time>
      <iterations>152070</iterations>
      <model name='ground_plane'>
        <pose frame=''>0 0 0 0 -0 0</pose>
        <scale>1 1 1</scale>
        <link name='link'>
          <pose frame=''>0 0 0 0 -0 0</pose>
          <velocity>0 0 0 0 -0 0</velocity>
          <acceleration>0 0 0 0 -0 0</acceleration>
          <wrench>0 0 0 0 -0 0</wrench>
        </link>
      </model>
      <model name='nexus_4wd_mecanum'>
        <pose frame=''>-0.000246 0.000476 0 -1e-06 -1e-06 4e-06</pose>
        <scale>1 1 1</scale>
        <link name='base_footprint'>
          <pose frame=''>-0.000246 0.000476 0 -1e-06 -1e-06 4e-06</pose>
          <velocity>-3e-05 0.001476 0.004962 0.028673 0.000537 1.4e-05</velocity>
          <acceleration>0.00535 -0.036498 10.0416 0.974211 -0.925914 0.034823</acceleration>
          <wrench>0.016391 -0.11183 30.7675 0 -0 0</wrench>
        </link>
        <link name='lower_left_wheel'>
          <pose frame=''>-0.150247 0.150476 0.05 -4e-06 0.000182 4e-06</pose>
          <velocity>-5e-06 4e-05 0.009394 0.024574 3e-06 1.4e-05</velocity>
          <acceleration>-0.021221 0.088353 22.2525 2.65377 0.000319 0.034667</acceleration>
          <wrench>-0.008157 0.033963 8.55386 0 -0 0</wrench>
        </link>
        <link name='lower_right_wheel'>
          <pose frame=''>-0.150246 -0.149524 0.05 3.14159 -0 4e-06</pose>
          <velocity>-1e-06 4e-05 0.000687 0.027419 0 1.4e-05</velocity>
          <acceleration>-0.011177 0.087687 1.06598 -0.564955 0.000333 0.034489</acceleration>
          <wrench>-0.004296 0.033707 0.409763 0 -0 0</wrench>
        </link>
        <link name='upper_left_wheel'>
          <pose frame=''>0.149753 0.150477 0.05 -4e-06 9e-06 4e-06</pose>
          <velocity>-5e-06 4.5e-05 0.009116 0.027564 0 1.4e-05</velocity>
          <acceleration>-0.021347 0.098453 18.5668 -0.850631 0.000332 0.03408</acceleration>
          <wrench>-0.008206 0.037845 7.1371 0 -0 0</wrench>
        </link>
        <link name='upper_right_wheel'>
          <pose frame=''>0.149754 -0.149523 0.050001 -3.14157 -4.4e-05 4e-06</pose>
          <velocity>-1e-06 4.5e-05 0.000615 0.021816 -1e-06 1.4e-05</velocity>
          <acceleration>-0.011078 0.099229 -2.29562 1.70485 0.000252 0.033962</acceleration>
          <wrench>-0.004258 0.038144 -0.882437 0 -0 0</wrench>
        </link>
      </model>
      <model name='unit_cylinder'>
        <pose frame=''>3 3.25 0.499993 -4e-06 -4e-06 -0</pose>
        <scale>1 1 1</scale>
        <link name='link'>
          <pose frame=''>3 3.25 0.499993 -4e-06 -4e-06 -0</pose>
          <velocity>0 0 0 0 -0 0</velocity>
          <acceleration>0 0 -9.8 0 -0 0</acceleration>
          <wrench>0 0 -9.8 0 -0 0</wrench>
        </link>
      </model>
      <model name='unit_cylinder_0'>
        <pose frame=''>6.5 4 0.499991 -0 -0 -0</pose>
        <scale>1 1 1</scale>
        <link name='link'>
          <pose frame=''>6.5 4 0.499991 -0 -0 -0</pose>
          <velocity>0 0 0 0 -0 0</velocity>
          <acceleration>0 0 -9.8 0 -0 0</acceleration>
          <wrench>0 0 -9.8 0 -0 0</wrench>
        </link>
      </model>
      <light name='sun'>
        <pose frame=''>0 0 10 0 -0 0</pose>
      </light>
    </state>
    <gui fullscreen='0'>
      <camera name='user_camera'>
        <pose frame=''>3.09911 -8.6398 7.36093 0 0.759643 1.74819</pose>
        <view_controller>orbit</view_controller>
        <projection_type>perspective</projection_type>
      </camera>
    </gui>
  </world>
</sdf>
